<?xml version="1.0" encoding="utf-8"?>
<!-- from https://github.com/vikashplus/mj_envs/tree/master/mj_envs/hand_manipulation_suite/assets -->
<!-- Information about door can be found in this paper: https://arxiv.org/pdf/1709.10087.pdf -->

<mujoco model="door">
  <asset>
    <texture file="../textures/wood.png" type="cube" name="wood" />
    <texture file="../textures/foil.png" type="cube" name="foil" />
    <material name="MatFoil" texture="foil" specular="1" shininess="0.3" rgba="0.9 0.9 0.9 1" />
    <material name="MatWood" texture="wood" texrepeat="3 3" specular="0.4" shininess="0.1" />
  </asset>
  <default>
    <default class="viz">
      <geom contype="0" conaffinity="0" group="1" />
    </default>
    <default class="coll">
      <geom group="0" />
    </default>
    <default class="site">
      <geom group="2" />
    </default>
  </default>
    <worldbody>
      <body>
      <body name="collision">
        <body name="frame" pos="0 0 0" quat="1 0 0 0">
            <inertial pos="1.0 0 0" quat="0.5 0.5 0.5 0.5" mass="7.85398" diaginertia="0.923301 0.764585 0.168533" />
            <!--<inertial pos="0.29 0 0" quat="0.5 0.5 0.5 0.5" mass="7.85398" diaginertia="0.923301 0.764585 0.168533" />-->
            <geom size="0.05 1." pos="0.0 0 0" type="cylinder" rgba="1 0 0 1" class="coll" name="l_frame"/>
            <geom size="0.05 1." pos="0.0 0 0" type="cylinder" material="MatWood" rgba="1 0 0 1" class="viz"/>
            <geom size="0.05 1." pos="2.1 0 0" type="cylinder" rgba="1 0 0 1" class="coll" name="r_frame"/>
            <geom size="0.05 1." pos="2.1 0 0" type="cylinder" material="MatWood" rgba="1 0 0 1" class="viz" />
            <site name="door_center" pos="1.05 0.0 0.0" size="0.025" class="site" rgba="0 0 1 0"/>
            <site name="goal"        pos="1.05 0.0 0.0" size="0.1" class="site" rgba="0 1 0 0.3"/>
            <body name="door" pos="1.05 0 0">
                <inertial pos="0.0296816 -0.00152345 0" quat="0.701072 0 0 0.713091" mass="0.1" diaginertia="0.0913751 0.0521615 0.043714" />
                <joint name="door_hinge" pos="1.05 0 0" axis="0 0 1" range="0.0 4.7" damping="0.001" frictionloss=".001" limited="true"/>
                <geom size="0.95 0.05 .99" type="box" friction="1 1 1" class="coll" name="door_box"/>
                <geom size="0.95 0.05 .99" type="box" friction="1 1 1" material="MatWood" class="viz"/>
                <geom size="0.05      .99" pos="0.95 0 0" type="cylinder"  class="coll" name="door_r_cyl"/>
                <geom size="0.05      .99" pos="0.95 0 0" type="cylinder" material="MatWood" class="viz" />
                <geom size="0.05      .99" pos="-0.95 0 0" type="cylinder"  class="coll" name="door_l_cyl" />
                <geom size="0.05      .99" pos="-0.95 0 0" type="cylinder" material="MatWood" class="viz" />
                <body name="latch" pos="-0.75 0 -0.025">
                    <inertial pos="-0.017762 0.0138544 0" quat="0.365653 0.605347 -0.36522 0.605365" mass="0.1" diaginertia="0.0483771 0.0410001 0.0111013" />
                    <geom size="0.05 0.15" quat="0.707388 0.706825 0 0" type="cylinder" material="MatFoil" class="viz" />
                    <geom size="0.02 0.1" pos="0 -0.15 -0.1" quat="1 0 0 0" type="capsule" material="MatFoil" class="viz"/>
                    <geom size="0.05 0.15" quat="0.707388 0.706825 0 0" type="cylinder" class="coll" name="handle_base"/>
                    <geom size="0.02 0.1" pos="0 -0.15 -0.1" quat="1 0 0 0" type="capsule" class="coll" name="handle"/>
                    <site name="door_handle" pos="0 -0.15 -0.1" size="0.025" class="site" rgba="1 0 0 1"/>
                </body>
            </body>
        <geom size="0.65 0.01 .99" pos="-0.65 0 0" type="box" friction="1 1 1" class="coll" name="wall_g0"/>
        <geom size="0.65 0.01 .99" pos="-0.65 0 0" type="box" friction="1 1 1" material="MatWood" class="viz"/>

        <geom size="0.65 0.01 .99" pos="2.75 0 0" type="box" friction="1 1 1" class="coll" name="wall_g1"/>
        <geom size="0.65 0.01 .99" pos="2.75 0 0" type="box" friction="1 1 1" material="MatWood" class="viz"/>

        <geom size="1.0  0.01 .99" pos="-1.3 -1.0 0" quat="0 0.707 0.707 0" type="box" friction="1 1 1" class="coll" name="wall_g2"/>
        <geom size="1.0  0.01 .99" pos="-1.3 -1.0 0" quat="0 0.707 0.707 0" type="box" friction="1 1 1" material="MatWood" class="viz"/>

        <geom size="1.0  0.01 .99" pos="3.4 -1.0 0" quat="0 0.707 0.707 0" type="box" friction="1 1 1" class="coll" name="wall_g3"/>
        <geom size="1.0  0.01 .99" pos="3.4 -1.0 0" quat="0 0.707 0.707 0" type="box" friction="1 1 1" material="MatWood" class="viz"/>
        </body>
      </body>
      </body>
    </worldbody>
</mujoco>
